#VRML_SIM R2022a utf8
WorldInfo {
}
Viewpoint {
  orientation 0.6982137051314429 0.0008339848272309474 -0.715888906490337 3.139878410069823
  position 2.162065551692849 2.8754422422114065 7.30990578738458
  follow "robot"
}
TexturedBackground {
}
TexturedBackgroundLight {
}
RectangleArena {
  translation 2.5 2.5 0
  floorSize 5 5
}
DEF robot Robot {
  translation 0.125 0.125 -0.000206461
  rotation 0 0 1 3.14159
  children [
    InertialUnit {
    }
    GPS {
    }
    DEF body Transform {
      translation 0 0 0.0415
      children [
        Shape {
          appearance PBRAppearance {
            baseColor 0 0 1
            roughness 1
            metalness 0
          }
          geometry Cylinder {
            height 0.08
            radius 0.045
          }
        }
      ]
    }
    HingeJoint {
      jointParameters HingeJointParameters {
        position 14.809636955439288
        anchor 0.045 0 0.025
      }
      device [
        RotationalMotor {
          name "motor_1"
        }
        PositionSensor {
          name "ps_1"
        }
      ]
      endPoint Solid {
        translation 0.045 0 0.025
        rotation 0.6695916733809867 0.3225019141808173 0.6690586717833937 2.5171856395186225
        children [
          DEF wheel Shape {
            appearance PBRAppearance {
              baseColor 1 0 0
              roughness 1
              metalness 0
            }
            geometry Cylinder {
              height 0.01
              radius 0.025
            }
          }
        ]
        boundingObject USE wheel
        physics DEF wheel_physics Physics {
        }
      }
    }
    HingeJoint {
      jointParameters HingeJointParameters {
        position 37.23808496491429
        anchor -0.045 0 0.025
      }
      device [
        RotationalMotor {
          name "motor_2"
        }
        PositionSensor {
          name "ps_2"
        }
      ]
      endPoint Solid {
        translation -0.045 0 0.025
        rotation -0.22290632583766148 0.949054588194654 -0.22272889019664627 1.6222662198297526
        children [
          USE wheel
        ]
        name "solid(1)"
        boundingObject USE wheel
        physics USE wheel_physics
      }
    }
    Solid {
      translation 0.015 -0.045 0.07
      children [
        DEF eye Shape {
          appearance PBRAppearance {
            baseColor 1 0 0
            roughness 1
            metalness 0
          }
          geometry Box {
            size 0.005 0.005 0.005
          }
        }
      ]
      name "solid(2)"
    }
    Solid {
      translation -0.015 -0.045 0.07
      children [
        USE eye
      ]
      name "solid(3)"
    }
  ]
  boundingObject USE body
  physics Physics {
  }
  controller "robot_controller"
}
SolidBox {
  translation 1.63 2.5 0.05
  size 0.75 1 0.1
  appearance PBRAppearance {
    baseColor 0.960784 0.47451 0
    roughness 0.5
    metalness 0
  }
}
SolidBox {
  translation 4.125 4.13 0.05
  name "box(1)"
  size 0.75 0.75 0.1
  appearance PBRAppearance {
    baseColor 0.333333 0.341176 0.32549
    roughness 0.5
    metalness 0
  }
}
SolidBox {
  translation 2.495 4 0.05
  name "box(2)"
  size 1 0.5 0.1
  appearance PBRAppearance {
    baseColor 0.203922 0.396078 0.643137
    roughness 0.5
    metalness 0
  }
}
SolidBox {
  translation 3.365 2.88 0.05
  name "box(8)"
  size 0.75 0.25 0.1
  appearance PBRAppearance {
    baseColor 0.458824 0.313725 0.482353
    roughness 0.5
    metalness 0
  }
}
SolidBox {
  translation 0.125 1.5 0.05
  name "box(9)"
  size 0.25 1 0.1
  appearance PBRAppearance {
    baseColor 0.8 0 0
    roughness 0.5
    metalness 0
  }
}
SolidBox {
  translation 0.745 4.25 0.05
  name "box(4)"
  size 0.5 1 0.1
  appearance PBRAppearance {
    baseColor 0.45098 0.823529 0.0862745
    roughness 0.5
    metalness 0
  }
}
SolidBox {
  translation 4.625 2 0.05
  name "box(7)"
  size 0.25 1 0.1
  appearance PBRAppearance {
    baseColor 0.729412 0.741176 0.713725
    roughness 0.5
    metalness 0
  }
}
SolidBox {
  translation 3.995 0.63 0.05
  name "box(5)"
  size 0.5 0.25 0.1
  appearance PBRAppearance {
    baseColor 0.768627 0.627451 0
    roughness 0.5
    metalness 0
  }
}
SolidBox {
  translation 2.995 1.75 0.05
  name "box(6)"
  size 0.5 0.5 0.1
  appearance PBRAppearance {
    baseColor 0.560784 0.34902 0.00784314
    roughness 0.5
    metalness 0
  }
}
SolidBox {
  translation 1.505 0.75 0.05
  name "box(3)"
  size 1 0.5 0.1
  appearance PBRAppearance {
    baseColor 0.988235 0.686275 0.243137
    roughness 0.5
    metalness 0
  }
}
