#VRML_SIM R2022a utf8
WorldInfo {
}
Viewpoint {
  orientation -0.6391944350496516 -0.013368691298735042 0.768928964400819 3.1737584583461373
  position 4.249708137953649 2.6923303154573004 8.441439276320734
  follow "robot"
}
TexturedBackground {
}
TexturedBackgroundLight {
}
RectangleArena {
  translation 2.5 2.5 0
  floorSize 5 5
}
DEF robot Robot {
  translation 0.125 0.125 -0.000206461
  rotation 0 0 1 3.14159
  children [
    InertialUnit {
    }
    GPS {
    }
    DEF body Transform {
      translation 0 0 0.0415
      children [
        Shape {
          appearance PBRAppearance {
            baseColor 0 0 1
            roughness 1
            metalness 0
          }
          geometry Cylinder {
            height 0.08
            radius 0.045
          }
        }
      ]
    }
    HingeJoint {
      jointParameters HingeJointParameters {
        position 14.809636955439288
        anchor 0.045 0 0.025
      }
      device [
        RotationalMotor {
          name "motor_1"
        }
        PositionSensor {
          name "ps_1"
        }
      ]
      endPoint Solid {
        translation 0.045 0 0.025
        rotation 0.6695916733809867 0.3225019141808173 0.6690586717833937 2.5171856395186225
        children [
          DEF wheel Shape {
            appearance PBRAppearance {
              baseColor 1 0 0
              roughness 1
              metalness 0
            }
            geometry Cylinder {
              height 0.01
              radius 0.025
            }
          }
        ]
        boundingObject USE wheel
        physics DEF wheel_physics Physics {
        }
      }
    }
    HingeJoint {
      jointParameters HingeJointParameters {
        position 37.23808496491429
        anchor -0.045 0 0.025
      }
      device [
        RotationalMotor {
          name "motor_2"
        }
        PositionSensor {
          name "ps_2"
        }
      ]
      endPoint Solid {
        translation -0.045 0 0.025
        rotation -0.22290632583766148 0.949054588194654 -0.22272889019664627 1.6222662198297526
        children [
          USE wheel
        ]
        name "solid(1)"
        boundingObject USE wheel
        physics USE wheel_physics
      }
    }
    Solid {
      translation 0.015 -0.045 0.07
      children [
        DEF eye Shape {
          appearance PBRAppearance {
            baseColor 1 0 0
            roughness 1
            metalness 0
          }
          geometry Box {
            size 0.005 0.005 0.005
          }
        }
      ]
      name "solid(2)"
    }
    Solid {
      translation -0.015 -0.045 0.07
      children [
        USE eye
      ]
      name "solid(3)"
    }
  ]
  boundingObject USE body
  physics Physics {
  }
  controller "robot_controller"
}
DEF wall_x Solid {
  translation 0.625 0.175 0
  children [
    Shape {
      appearance PBRAppearance {
        baseColor 0 0 0
        roughness 1
        metalness 0
      }
      geometry Box {
        size 0.125 0.375 0.25
      }
    }
  ]
  name "wall"
}
DEF wall_x Solid {
  translation 4.355 4.805 0
  children [
    Shape {
      appearance PBRAppearance {
        baseColor 0 0 0
        roughness 1
        metalness 0
      }
      geometry Box {
        size 0.125 0.375 0.25
      }
    }
  ]
  name "wall(20)"
}
DEF wall_x Solid {
  translation 0.385 1.695 0
  rotation 0 1 0 0
  children [
    Shape {
      appearance PBRAppearance {
        baseColor 0 0 0
        roughness 1
        metalness 0
      }
      geometry Box {
        size 0.125 0.775 0.25
      }
    }
  ]
  name "wall(4)"
}
DEF wall_x Solid {
  translation 1.835 1.695 0
  rotation 0 1 0 0
  children [
    Shape {
      appearance PBRAppearance {
        baseColor 0 0 0
        roughness 1
        metalness 0
      }
      geometry Box {
        size 0.125 0.775 0.25
      }
    }
  ]
  name "wall(2)"
}
DEF wall_x Solid {
  translation 1.835 4.205 0
  rotation 0 1 0 0
  children [
    Shape {
      appearance PBRAppearance {
        baseColor 0 0 0
        roughness 1
        metalness 0
      }
      geometry Box {
        size 0.125 0.775 0.25
      }
    }
  ]
  name "wall(17)"
}
DEF wall_x Solid {
  translation 2.635 1.095 0
  rotation 0 1 0 0
  children [
    Shape {
      appearance PBRAppearance {
        baseColor 0 0 0
        roughness 1
        metalness 0
      }
      geometry Box {
        size 0.125 1 0.25
      }
    }
  ]
  name "wall(6)"
}
DEF wall_x Solid {
  translation 3.135 3.355 0
  rotation 0 1 0 0
  children [
    Shape {
      appearance PBRAppearance {
        baseColor 0 0 0
        roughness 1
        metalness 0
      }
      geometry Box {
        size 0.125 1.5 0.25
      }
    }
  ]
  name "wall(14)"
}
DEF wall_x Solid {
  translation 4.135 0.845 0
  rotation 0 1 0 0
  children [
    Shape {
      appearance PBRAppearance {
        baseColor 0 0 0
        roughness 1
        metalness 0
      }
      geometry Box {
        size 0.125 1 0.25
      }
    }
  ]
  name "wall(8)"
}
DEF wall_x Solid {
  translation 0.625 3.655 0
  rotation 0 1 0 0
  children [
    Shape {
      appearance PBRAppearance {
        baseColor 0 0 0
        roughness 1
        metalness 0
      }
      geometry Box {
        size 0.125 1 0.25
      }
    }
  ]
  name "wall(18)"
}
DEF wall_y Solid {
  translation 0.8525 0.375 0
  rotation 0 0 1 1.5708
  children [
    Shape {
      appearance PBRAppearance {
        baseColor 0 0 0
        roughness 1
        metalness 0
      }
      geometry Box {
        size 0.125 0.575 0.25
      }
    }
  ]
  name "wall(21)"
}
DEF wall_y Solid {
  translation 4.13248 4.625 0
  rotation 0 0 1 1.5708
  children [
    Shape {
      appearance PBRAppearance {
        baseColor 0 0 0
        roughness 1
        metalness 0
      }
      geometry Box {
        size 0.125 0.575 0.25
      }
    }
  ]
  name "wall(19)"
}
DEF wall_y Solid {
  translation 2.4025 1.625 0
  rotation 0 0 1 1.5708
  children [
    Shape {
      appearance PBRAppearance {
        baseColor 0 0 0
        roughness 1
        metalness 0
      }
      geometry Box {
        size 0.125 1 0.25
      }
    }
  ]
  name "wall(5)"
}
DEF wall_y Solid {
  translation 3.8625 1.375 0
  rotation 0 0 1 1.5708
  children [
    Shape {
      appearance PBRAppearance {
        baseColor 0 0 0
        roughness 1
        metalness 0
      }
      geometry Box {
        size 0.125 0.6625 0.25
      }
    }
  ]
  name "wall(9)"
}
DEF wall_y Solid {
  translation 3.7325 0.375 0
  rotation 0 0 1 1.5708
  children [
    Shape {
      appearance PBRAppearance {
        baseColor 0 0 0
        roughness 1
        metalness 0
      }
      geometry Box {
        size 0.125 0.925 0.25
      }
    }
  ]
  name "wall(10)"
}
DEF wall_y Solid {
  translation 4.6325 2.125 0
  rotation 0 0 1 1.5708
  children [
    Shape {
      appearance PBRAppearance {
        baseColor 0 0 0
        roughness 1
        metalness 0
      }
      geometry Box {
        size 0.125 0.775 0.25
      }
    }
  ]
  name "wall(13)"
}
DEF wall_y Solid {
  translation 4.5725 0.625 0
  rotation 0 0 1 1.5708
  children [
    Shape {
      appearance PBRAppearance {
        baseColor 0 0 0
        roughness 1
        metalness 0
      }
      geometry Box {
        size 0.125 1 0.25
      }
    }
  ]
  name "wall(7)"
}
DEF wall_y Solid {
  translation 1.1025 1.375 0
  rotation 0 0 1 1.5708
  children [
    Shape {
      appearance PBRAppearance {
        baseColor 0 0 0
        roughness 1
        metalness 0
      }
      geometry Box {
        size 0.125 1.5 0.25
      }
    }
  ]
  name "wall(1)"
}
DEF wall_y Solid {
  translation 1.1025 3.125 0
  rotation 0 0 1 1.5708
  children [
    Shape {
      appearance PBRAppearance {
        baseColor 0 0 0
        roughness 1
        metalness 0
      }
      geometry Box {
        size 0.125 1.5 0.25
      }
    }
  ]
  name "wall(11)"
}
DEF wall_y Solid {
  translation 2.3425 3.875 0
  rotation 0 0 1 1.5708
  children [
    Shape {
      appearance PBRAppearance {
        baseColor 0 0 0
        roughness 1
        metalness 0
      }
      geometry Box {
        size 0.125 1.5 0.25
      }
    }
  ]
  name "wall(16)"
}
DEF wall_y Solid {
  translation 3.8625 3.625 0
  rotation 0 0 1 1.5708
  children [
    Shape {
      appearance PBRAppearance {
        baseColor 0 0 0
        roughness 1
        metalness 0
      }
      geometry Box {
        size 0.125 1.5 0.25
      }
    }
  ]
  name "wall(15)"
}
DEF wall_y Solid {
  translation 3.1025 2.625 0
  rotation 0 0 1 1.5708
  children [
    Shape {
      appearance PBRAppearance {
        baseColor 0 0 0
        roughness 1
        metalness 0
      }
      geometry Box {
        size 0.125 1.5 0.25
      }
    }
  ]
  name "wall(12)"
}
DEF wall_y Solid {
  translation 0.4625 2.125 0
  rotation 0 0 1 1.5708
  children [
    Shape {
      appearance PBRAppearance {
        baseColor 0 0 0
        roughness 1
        metalness 0
      }
      geometry Box {
        size 0.125 0.925 0.25
      }
    }
  ]
  name "wall(3)"
}
