#VRML_SIM R2022a utf8
WorldInfo {
}
Viewpoint {
  orientation -0.47845533266022944 -0.5449561874848612 0.6885515582517795 4.471729779942512
  position 0.6344916736079704 1.7167783782574424 3.1455203401999623
  follow "robot"
}
TexturedBackground {
}
TexturedBackgroundLight {
}
RectangleArena {
  translation 1.5 1.5 0
  floorSize 3 3
}
DEF robot Robot {
  translation 0.125 0.125 -0.000206461
  rotation 0 0 1 3.14159
  children [
    InertialUnit {
    }
    GPS {
    }
    DEF body Transform {
      translation 0 0 0.0415
      children [
        Shape {
          appearance PBRAppearance {
            baseColor 0 0 1
            roughness 1
            metalness 0
          }
          geometry Cylinder {
            height 0.08
            radius 0.045
          }
        }
      ]
    }
    HingeJoint {
      jointParameters HingeJointParameters {
        position 14.809636955439288
        anchor 0.045 0 0.025
      }
      device [
        RotationalMotor {
          name "motor_1"
        }
        PositionSensor {
          name "ps_1"
        }
      ]
      endPoint Solid {
        translation 0.045 0 0.025
        rotation 0.6695916733809867 0.3225019141808173 0.6690586717833937 2.5171856395186225
        children [
          DEF wheel Shape {
            appearance PBRAppearance {
              baseColor 1 0 0
              roughness 1
              metalness 0
            }
            geometry Cylinder {
              height 0.01
              radius 0.025
            }
          }
        ]
        boundingObject USE wheel
        physics DEF wheel_physics Physics {
        }
      }
    }
    HingeJoint {
      jointParameters HingeJointParameters {
        position 37.23808496491429
        anchor -0.045 0 0.025
      }
      device [
        RotationalMotor {
          name "motor_2"
        }
        PositionSensor {
          name "ps_2"
        }
      ]
      endPoint Solid {
        translation -0.045 0 0.025
        rotation -0.22290632583766148 0.949054588194654 -0.22272889019664627 1.6222662198297526
        children [
          USE wheel
        ]
        name "solid(1)"
        boundingObject USE wheel
        physics USE wheel_physics
      }
    }
    Solid {
      translation 0.015 -0.045 0.07
      children [
        DEF eye Shape {
          appearance PBRAppearance {
            baseColor 1 0 0
            roughness 1
            metalness 0
          }
          geometry Box {
            size 0.005 0.005 0.005
          }
        }
      ]
      name "solid(2)"
    }
    Solid {
      translation -0.015 -0.045 0.07
      children [
        USE eye
      ]
      name "solid(3)"
    }
  ]
  boundingObject USE body
  physics Physics {
  }
  controller "robot_controller"
}
DEF PINK_BOX Solid {
  translation 0.76 1.42 0.05
  rotation 0 0 1 1.5708
  children [
    Shape {
      appearance PBRAppearance {
        baseColor 1 0.1 0.3
        roughness 0.16827074099999995
        metalness 0
      }
      geometry DEF BOX3 Box {
        size 0.2 0.4 0.2
      }
    }
  ]
  name "red box"
  boundingObject Shape {
    appearance PBRAppearance {
      roughness 1.1102230246251565e-16
      metalness 0
    }
    geometry USE BOX3
  }
}
DEF wall_x Solid {
  translation 0.375 0.175 0
  children [
    Shape {
      appearance PBRAppearance {
        baseColor 0 0 0
        roughness 1
        metalness 0
      }
      geometry Box {
        size 0.125 0.375 0.25
      }
    }
  ]
  name "wall"
}
DEF wall_x Solid {
  translation 1.125 0.5 0
  children [
    Shape {
      appearance PBRAppearance {
        baseColor 0 0 0
        roughness 1
        metalness 0
      }
      geometry Box {
        size 0.125 0.375 0.25
      }
    }
  ]
  name "wall(2)"
}
DEF wall_y Solid {
  translation 0.725 0.375 -1.63365e-06
  rotation -2.327229999987396e-06 -2.327229999987396e-06 -0.9999999999945841 -1.5707953071795862
  children [
    Shape {
      appearance PBRAppearance {
        baseColor 0 0 0
        roughness 1
        metalness 0
      }
      geometry Box {
        size 0.125 0.825 0.25
      }
    }
  ]
  name "wall(1)"
}
